<?xml version="1.0" encoding="utf-8"?>
<!-- This URDF was automatically created by SolidWorks to URDF Exporter! Originally created by Stephen Brawner (brawner@gmail.com) 
     Commit Version: 1.6.0-4-g7f85cfe  Build Version: 1.6.7995.38578
     For more information, please see http://wiki.ros.org/sw_urdf_exporter -->
<robot name="arm_lcr_description">
  <link
    name="base_link">
    <inertial>
      <origin
        xyz="-0.0539149578548648 1.57261934077835E-06 0.0332773857416667"
        rpy="0 0 0" />
      <mass
        value="1.08324725457804" />
      <inertia
        ixx="0.00157344948847675"
        ixy="-1.12829086180671E-09"
        ixz="5.33124037789552E-06"
        iyy="0.0040231125989147"
        iyz="-2.98868560775735E-08"
        izz="0.00536317412804565" />
    </inertial>
    <visual>
      <origin
        xyz="0 0 0"
        rpy="0 0 0" />
      <geometry>
        <mesh
          filename="package://arm_lcr_description/meshes/base_link.STL" />
      </geometry>
      <material
        name="">
        <color
          rgba="0.796078431372549 0.823529411764706 0.937254901960784 1" />
      </material>
    </visual>
    <collision>
      <origin
        xyz="0 0 0"
        rpy="0 0 0" />
      <geometry>
        <mesh
          filename="package://arm_lcr_description/meshes/base_link.STL" />
      </geometry>
    </collision>
  </link>
  <link
    name="link1">
    <inertial>
      <origin
        xyz="0.0290369959505637 0.00392673836922251 -0.0691391188190973"
        rpy="0 0 0" />
      <mass
        value="4.11475891139606" />
      <inertia
        ixx="0.00301779800607539"
        ixy="4.34907717188804E-05"
        ixz="-0.000208069701480735"
        iyy="0.00389032149455748"
        iyz="1.59347759647464E-05"
        izz="0.00268946406649663" />
    </inertial>
    <visual>
      <origin
        xyz="0 0 0"
        rpy="0 0 0" />
      <geometry>
        <mesh
          filename="package://arm_lcr_description/meshes/link1.STL" />
      </geometry>
      <material
        name="">
        <color
          rgba="0.866666666666667 0.866666666666667 0.890196078431372 1" />
      </material>
    </visual>
    <collision>
      <origin
        xyz="0 0 0"
        rpy="0 0 0" />
      <geometry>
        <mesh
          filename="package://arm_lcr_description/meshes/link1.STL" />
      </geometry>
    </collision>
  </link>
  <joint
    name="joint1"
    type="revolute">
    <origin
      xyz="0 0 0.169"
      rpy="0 0 0" />
    <parent
      link="base_link" />
    <child
      link="link1" />
    <axis
      xyz="0 0 1" />
    <limit
      lower="-3.14"
      upper="3.14"
      effort="100"
      velocity="3.000000001" />
  </joint>
  <link
    name="link2">
    <inertial>
      <origin
        xyz="0.0903884076777632 -0.000120715476666713 0.0448943512220614"
        rpy="0 0 0" />
      <mass
        value="2.38987246296436" />
      <inertia
        ixx="0.000939880922658595"
        ixy="1.28611883592931E-06"
        ixz="-1.93876099056265E-07"
        iyy="0.0143982647000054"
        iyz="3.25586872098753E-07"
        izz="0.0148822149795595" />
    </inertial>
    <visual>
      <origin
        xyz="0 0 0"
        rpy="0 0 0" />
      <geometry>
        <mesh
          filename="package://arm_lcr_description/meshes/link2.STL" />
      </geometry>
      <material
        name="">
        <color
          rgba="0.647058823529412 0.619607843137255 0.588235294117647 1" />
      </material>
    </visual>
    <collision>
      <origin
        xyz="0 0 0"
        rpy="0 0 0" />
      <geometry>
        <mesh
          filename="package://arm_lcr_description/meshes/link2.STL" />
      </geometry>
    </collision>
  </link>
  <joint
    name="joint2"
    type="revolute">
    <origin
      xyz="0.064418 0 0"
      rpy="1.5708 -1.5708 -3.1416" />
    <parent
      link="link1" />
    <child
      link="link2" />
    <axis
      xyz="0 0 1" />
    <limit
      lower="-3.14"
      upper="3.14"
      effort="100"
      velocity="3.00000001" />
  </joint>
  <link
    name="link3">
    <inertial>
      <origin
        xyz="-0.00480501626264607 0.0021139941286724 0.0211236757719251"
        rpy="0 0 0" />
      <mass
        value="1.08870632017772" />
      <inertia
        ixx="0.000430792050794806"
        ixy="6.25652387631402E-09"
        ixz="2.89417241374556E-07"
        iyy="0.000347781961784541"
        iyz="-4.52784032099191E-06"
        izz="0.000487143846518166" />
    </inertial>
    <visual>
      <origin
        xyz="0 0 0"
        rpy="0 0 0" />
      <geometry>
        <mesh
          filename="package://arm_lcr_description/meshes/link3.STL" />
      </geometry>
      <material
        name="">
        <color
          rgba="0.615686274509804 0.643137254901961 0.674509803921569 1" />
      </material>
    </visual>
    <collision>
      <origin
        xyz="0 0 0"
        rpy="0 0 0" />
      <geometry>
        <mesh
          filename="package://arm_lcr_description/meshes/link3.STL" />
      </geometry>
    </collision>
  </link>
  <joint
    name="joint3"
    type="revolute">
    <origin
      xyz="0.305 0 0"
      rpy="0 0 0" />
    <parent
      link="link2" />
    <child
      link="link3" />
    <axis
      xyz="0 0 1" />
    <limit
      lower="-3.14"
      upper="3.14"
      effort="100"
      velocity="3.00000001" />
  </joint>
  <link
    name="link4">
    <inertial>
      <origin
        xyz="-2.5424E-05 0.010879 -0.14272"
        rpy="0 0 0" />
      <mass
        value="1.4353" />
      <inertia
        ixx="0.0017023"
        ixy="2.9482E-07"
        ixz="1.5814E-06"
        iyy="0.0018769"
        iyz="-3.5822E-06"
        izz="0.00042454" />
    </inertial>
    <visual>
      <origin
        xyz="0 0 0"
        rpy="0 0 0" />
      <geometry>
        <mesh
          filename="package://arm_lcr_description/meshes/link4.STL" />
      </geometry>
      <material
        name="">
        <color
          rgba="0.75294 0.75294 0.75294 1" />
      </material>
    </visual>
    <collision>
      <origin
        xyz="0 0 0"
        rpy="0 0 0" />
      <geometry>
        <mesh
          filename="package://arm_lcr_description/meshes/link4.STL" />
      </geometry>
    </collision>
  </link>
  <joint
    name="joint4"
    type="revolute">
    <origin
      xyz="0 0.22563 0"
      rpy="-1.5708 0 0" />
    <parent
      link="link3" />
    <child
      link="link4" />
    <axis
      xyz="0 0 1" />
    <limit
      lower="-3.14"
      upper="3.14"
      effort="100"
      velocity="3.000000001" />
  </joint>
  <link
    name="link5">
    <inertial>
      <origin
        xyz="0.0028991 2.7671E-05 -0.012589"
        rpy="0 0 0" />
      <mass
        value="0.40389" />
      <inertia
        ixx="8.4177E-05"
        ixy="-7.2261E-09"
        ixz="2.1205E-08"
        iyy="7.7816E-05"
        iyz="-3.4205E-08"
        izz="0.00010983" />
    </inertial>
    <visual>
      <origin
        xyz="0 0 0"
        rpy="0 0 0" />
      <geometry>
        <mesh
          filename="package://arm_lcr_description/meshes/link5.STL" />
      </geometry>
      <material
        name="">
        <color
          rgba="0.64706 0.61961 0.58824 1" />
      </material>
    </visual>
    <collision>
      <origin
        xyz="0 0 0"
        rpy="0 0 0" />
      <geometry>
        <mesh
          filename="package://arm_lcr_description/meshes/link5.STL" />
      </geometry>
    </collision>
  </link>
  <joint
    name="joint5"
    type="revolute">
    <origin
      xyz="0 0 0"
      rpy="1.5708 0 0" />
    <parent
      link="link4" />
    <child
      link="link5" />
    <axis
      xyz="0 0 1" />
    <limit
      lower="-3.14"
      upper="3.14"
      effort="100"
      velocity="3.00000001" />
  </joint>
  <link
    name="link6">
    <inertial>
      <origin
        xyz="0.0016961 0.0016533 0.047315"
        rpy="0 0 0" />
      <mass
        value="0.017789" />
      <inertia
        ixx="2.941E-06"
        ixy="2.7268E-07"
        ixz="2.7295E-07"
        iyy="3.2874E-06"
        iyz="2.7166E-07"
        izz="4.0086E-06" />
    </inertial>
    <visual>
      <origin
        xyz="0 0 0"
        rpy="0 0 0" />
      <geometry>
        <mesh
          filename="package://arm_lcr_description/meshes/link6.STL" />
      </geometry>
      <material
        name="">
        <color
          rgba="0.79608 0.82353 0.93725 1" />
      </material>
    </visual>
    <collision>
      <origin
        xyz="0 0 0"
        rpy="0 0 0" />
      <geometry>
        <mesh
          filename="package://arm_lcr_description/meshes/link6.STL" />
      </geometry>
    </collision>
  </link>
  <joint
    name="joint6"
    type="revolute">
    <origin
      xyz="-0.09385 0 0"
      rpy="1.5708 0 1.5708" />
    <parent
      link="link5" />
    <child
      link="link6" />
    <axis
      xyz="0 0 1" />
    <limit
      lower="-3.14"
      upper="3.14"
      effort="100"
      velocity="3.000000001" />
  </joint>

  <link name="world"/>

  <joint name="fixed" type="fixed">
      <parent link="world"/>
      <child link="base_link"/>
  </joint>

</robot>
